import asyncio
import pytest
import time

from unittest.mock import AsyncMock, MagicMock, create_autospec

from freshpointsync.update._update import SafeAsyncTaskRunner


@pytest.mark.asyncio
async def test_run_async_success():
    func = AsyncMock()
    func.return_value = 42
    runner = SafeAsyncTaskRunner()
    task = runner.run_async(func)
    result = await task
    assert result == 42
    func.assert_called_once()


@pytest.mark.asyncio
async def test_run_async_exception_run_safe():
    func = AsyncMock()
    func.side_effect = ValueError("Something went wrong")
    runner = SafeAsyncTaskRunner()
    task = runner.run_async(func, run_safe=True)
    result = -1
    result = await task
    assert result is None  # err is caught, result is set to None
    func.assert_called_once()


@pytest.mark.asyncio
async def test_run_async_exception_run_unsafe():
    func = AsyncMock()
    func.side_effect = ValueError("Something went wrong")
    runner = SafeAsyncTaskRunner()
    task = runner.run_async(func, run_safe=False)
    result = -1
    with pytest.raises(ValueError):
        result = await task
    assert result == -1  # err is propagated, result is not changed
    func.assert_called_once()


@pytest.mark.asyncio
async def test_run_sync_success():
    func = MagicMock()
    func.return_value = 42
    runner = SafeAsyncTaskRunner()
    task = runner.run_sync(func)
    result = await task
    assert result == 42
    func.assert_called_once()


@pytest.mark.asyncio
async def test_run_sync_exception_run_safe():
    func = MagicMock()
    func.__name__ = "func"
    func.side_effect = ValueError("Something went wrong")
    runner = SafeAsyncTaskRunner()
    task = runner.run_sync(func, run_safe=True)
    result = -1
    result = await task
    assert result is None  # err is caught, result is set to None
    func.assert_called_once()


@pytest.mark.asyncio
async def test_run_sync_exception_run_unsafe():
    func = MagicMock()
    func.side_effect = ValueError("Something went wrong")
    runner = SafeAsyncTaskRunner()
    task = runner.run_sync(func, run_safe=False)
    result = -1
    with pytest.raises(ValueError):
        result = await task
    assert result == -1  # err is propagated, result is not changed
    func.assert_called_once()


@pytest.mark.asyncio
async def test_run_sync_with_params():

    def concat(foo: str, bar: str) -> str:
        """Used as a source for `create_autospec`."""
        return f'{foo}{bar}'

    func = create_autospec(concat)
    func.return_value = "foobar"
    runner = SafeAsyncTaskRunner()
    task = runner.run_sync(func, "foo", "bar")
    result = await task
    assert result == "foobar"
    func.assert_called_once_with("foo", "bar")


@pytest.mark.asyncio
async def test_await_all():
    func1 = AsyncMock()
    func2 = AsyncMock()
    func3 = MagicMock()
    func4 = MagicMock()
    runner = SafeAsyncTaskRunner()
    task1 = runner.run_async(func1)
    task2 = runner.run_async(func2)
    task3 = runner.run_sync(func3)
    task4 = runner.run_sync(func4)
    await runner.await_all()
    func1.assert_called_once()
    func2.assert_called_once()
    func3.assert_called_once()
    func4.assert_called_once()
    assert task1.done() is True
    assert task2.done() is True
    assert task3.done() is True
    assert task4.done() is True


@pytest.mark.asyncio
async def test_await_all_exception_run_safe():
    func1 = AsyncMock()
    func1.return_value = 42
    func2 = MagicMock()
    func2.return_value = 42
    func2.side_effect = ValueError("Something went wrong")
    runner = SafeAsyncTaskRunner()
    task1 = runner.run_async(func1)
    task2 = runner.run_sync(func2, run_safe=True)
    await runner.await_all()
    func1.assert_called_once()
    func2.assert_called_once()
    assert task1.done() is True
    assert task2.done() is True
    assert task1.result() == 42
    assert task2.result() is None


@pytest.mark.asyncio
async def test_await_all_exception_run_unsafe():
    func1 = AsyncMock()
    func1.return_value = 42
    func2 = MagicMock()
    func2.return_value = 42
    func2.side_effect = ValueError("Something went wrong")
    runner = SafeAsyncTaskRunner()
    task1 = runner.run_async(func1)
    task2 = runner.run_sync(func2, run_safe=False)
    with pytest.raises(ValueError):
        await runner.await_all()
    func1.assert_called_once()
    func2.assert_called_once()
    assert task1.done() is True
    assert task2.done() is True
    assert task1.result() == 42
    with pytest.raises(ValueError):
        assert task2.result() == 42


@pytest.mark.asyncio
async def test_cancel_all():

    def sync_func():
        for _ in range(2):
            time.sleep(0.5)
        return 42

    async def async_func():
        for _ in range(2):
            await asyncio.sleep(0.5)
        return 42

    runner = SafeAsyncTaskRunner()
    task1 = runner.run_async(async_func, run_safe=True)
    task2 = runner.run_async(async_func, run_safe=True)
    task3 = runner.run_sync(sync_func, run_safe=True)
    task4 = runner.run_sync(sync_func, run_safe=True)
    await runner.cancel_all()
    assert task1.cancelled() is True
    assert task2.cancelled() is True
    assert task3.cancelled() is True
    assert task4.cancelled() is True
